Workbook

Sheet Ing statnice jun 2018
A1: Štátne skúšky, letný semester 2017/2018 - inžinierske štúdium
N2: Obhajoba hodnotenie | P2: Prospech | R2: Ďalšie informácie | U2: Návrh - cena akákoľvek | V2: Návrh na ocenenie z komisií za prácu (CR, CD, UI SAV, IET, PLD) | AB2: Ocenenie za prospech (MCL, CL) | AE2: Súťaže (IT SPY, ING CENA)
A3: Por.č. | B3: uzavreté štúdium A/N | C3: Priezvisko, meno, titul | F3: štud.program | G3: Dátum ŠS | H3: Komisia č. | I3: predseda komisie | J3: tajomník | K3: názov diplomovej práce | L3: vedúci | M3: oponent | N3: oponent | O3: komisia | P3: VŠP- nekompletné za inž.štúdium | Q3: VŠP- za celé inž.štúdium | R3: hlási sa na PhD. | S3: DP3 v AJ | T3: ŠS opravný termín | U3: Automatický návrh A / N | V3: Návrh - Poradie | W3: článok iný A/N | X3: článok IIT SRC A/N | Y3: Automatický návrh | Z3: Návrh do RŠP | AA3: Konečné rozhodnutie (RŠP) | AB3: Automatický návrh | AC3: Návrh do RŠP | AD3: Konečné rozhodnutie (RŠP) | AE3: Konečné rozhodnutie (RŠP) | AF3: potvrdenie IET - kto nie
A4: 36 | B4: A | C4: Gondová | D4: Veronika | E4: Bc. | F4: IS 2 | G4: 43262 | H4: 1p-IS | I4: Bieliková | J4: Pecár | K4: Modelovanie používateľa v doméne e-obchodu | L4: prof. Ing. Mária Bieliková, PhD. | M4: Ing. Ivan Srba, PhD. | N4: A | O4: A | P4: 1.13 | Q4: 1.12 | S4: A | U4: =IF(OR(V4<>"",Y4<>"",AB4<>""),"Navrh","") -> Navrh | V4: 1 | W4: A 3x | Y4: =IF(Q4<>"",IF(Q4<=1.2,IF(O4="A","CR",IF(V4<>"",IF(Parametre_2018!N$4=1,IF(LEFT(V4,1)="1",IF(V4<>"",IF(Parametre_2018!O$4<>"",IF(N4<=Parametre_2018!O$4,IF(V4<>"",IF(Parametre_2018!P$4<>"",IF(O4<=Parametre_2018!P$4,"PLD",""),"PLD"),""),""),IF(V4<>"",IF(Parametre_2018!P$4<>"",IF(O4<=Parametre_2018!P$4,"PLD",""),"PLD"),"")),""),""),IF(V4<>"",IF(Parametre_2018!O$4<>"",IF(N4<=Parametre_2018!O$4,IF(V4<>"",IF(Parametre_2018!P$4<>"",IF(O4<=Parametre_2018!P$4,"PLD",""),"PLD"),""),""),IF(V4<>"",IF(Parametre_2018!P$4<>"",IF(O4<=Parametre_2018!P$4,"PLD",""),"PLD"),"")),"")),"")),IF(V4<>"",IF(Parametre_2018!N$4=1,IF(LEFT(V4,1)="1",IF(V4<>"",IF(Parametre_2018!O$4<>"",IF(N4<=Parametre_2018!O$4,IF(V4<>"",IF(Parametre_2018!P$4<>"",IF(O4<=Parametre_2018!P$4,"PLD",""),"PLD"),""),""),IF(V4<>"",IF(Parametre_2018!P$4<>"",IF(O4<=Parametre_2018!P$4,"PLD",""),"PLD"),"")),""),""),IF(V4<>"",IF(Parametre_2018!O$4<>"",IF(N4<=Parametre_2018!O$4,IF(V4<>"",IF(Parametre_2018!P$4<>"",IF(O4<=Parametre_2018!P$4,"PLD",""),"PLD"),""),""),IF(V4<>"",IF(Parametre_2018!P$4<>"",IF(O4<=Parametre_2018!P$4,"PLD",""),"PLD"),"")),"")),"")),"") -> CR | Z4: CR | AA4: CR | AB4: =IF(Q4<>"",IF(Q4<=Parametre_2018!B$4,IF(Parametre_2018!C$4<>"",IF(N4<=Parametre_2018!C$4,IF(Parametre_2018!D$4<>"",IF(O4<=Parametre_2018!D$4,"MCL",IF(Parametre_2018!I$4<>"",IF(N4<=Parametre_2018!I$4,IF(Parametre_2018!J$4<>"",IF(O4<=Parametre_2018!J$4,"CL",""),"CL"),""),IF(Parametre_2018!J$4<>"",IF(O4<=Parametre_2018!J$4,"CL",""),"CL"))),"MCL"),IF(Parametre_2018!I$4<>"",IF(N4<=Parametre_2018!I$4,IF(Parametre_2018!J$4<>"",IF(O4<=Parametre_2018!J$4,"CL",""),"CL"),""),IF(Parametre_2018!J$4<>"",IF(O4<=Parametre_2018!J$4,"CL",""),"CL"))),IF(Parametre_2018!D$4<>"",IF(O4<=Parametre_2018!D$4,"MCL",IF(Parametre_2018!I$4<>"",IF(N4<=Parametre_2018!I$4,IF(Parametre_2018!J$4<>"",IF(O4<=Parametre_2018!J$4,"CL",""),"CL"),""),IF(Parametre_2018!J$4<>"",IF(O4<=Parametre_2018!J$4,"CL",""),"CL"))),"MCL")),IF(Q4<>"",IF(AND(Q4>Parametre_2018!B$4,Q4<=Parametre_2018!H$4),IF(Parametre_2018!I$4<>"",IF(N4<=Parametre_2018!I$4,IF(Parametre_2018!J$4<>"",IF(O4<=Parametre_2018!J$4,"CL",""),"CL"),""),IF(Parametre_2018!J$4<>"",IF(O4<=Parametre_2018!J$4,"CL",""),"CL")),""),"")),"") -> MCL | AE4: IT Spy - Top
A5: 46 | B5: A | C5: Ilavský | D5: Martin | E5: Bc. | F5: SI 2 | G5: 43262 | H5: 6p-IS-SI | I5: Chudá | J5: Petrík | K5: Simulácie útočných scenárov v mobilných ad hoc sieťach | L5: Ing. Jozef Filipek | M5: Ing. Ján Laštinec, PhD. | N5: A | O5: A | P5: 1.23 | Q5: 1.18 | U5: =IF(OR(V5<>"",Y5<>"",AB5<>""),"Navrh","") -> Navrh | V5: 1 | W5: A | Y5: =IF(Q5<>"",IF(Q5<=1.2,IF(O5="A","CR",IF(V5<>"",IF(Parametre_2018!N$4=1,IF(LEFT(V5,1)="1",IF(V5<>"",IF(Parametre_2018!O$4<>"",IF(N5<=Parametre_2018!O$4,IF(V5<>"",IF(Parametre_2018!P$4<>"",IF(O5<=Parametre_2018!P$4,"PLD",""),"PLD"),""),""),IF(V5<>"",IF(Parametre_2018!P$4<>"",IF(O5<=Parametre_2018!P$4,"PLD",""),"PLD"),"")),""),""),IF(V5<>"",IF(Parametre_2018!O$4<>"",IF(N5<=Parametre_2018!O$4,IF(V5<>"",IF(Parametre_2018!P$4<>"",IF(O5<=Parametre_2018!P$4,"PLD",""),"PLD"),""),""),IF(V5<>"",IF(Parametre_2018!P$4<>"",IF(O5<=Parametre_2018!P$4,"PLD",""),"PLD"),"")),"")),"")),IF(V5<>"",IF(Parametre_2018!N$4=1,IF(LEFT(V5,1)="1",IF(V5<>"",IF(Parametre_2018!O$4<>"",IF(N5<=Parametre_2018!O$4,IF(V5<>"",IF(Parametre_2018!P$4<>"",IF(O5<=Parametre_2018!P$4,"PLD",""),"PLD"),""),""),IF(V5<>"",IF(Parametre_2018!P$4<>"",IF(O5<=Parametre_2018!P$4,"PLD",""),"PLD"),"")),""),""),IF(V5<>"",IF(Parametre_2018!O$4<>"",IF(N5<=Parametre_2018!O$4,IF(V5<>"",IF(Parametre_2018!P$4<>"",IF(O5<=Parametre_2018!P$4,"PLD",""),"PLD"),""),""),IF(V5<>"",IF(Parametre_2018!P$4<>"",IF(O5<=Parametre_2018!P$4,"PLD",""),"PLD"),"")),"")),"")),"") -> CR | Z5: CR | AA5: CR | AB5: =IF(Q5<>"",IF(Q5<=Parametre_2018!B$4,IF(Parametre_2018!C$4<>"",IF(N5<=Parametre_2018!C$4,IF(Parametre_2018!D$4<>"",IF(O5<=Parametre_2018!D$4,"MCL",IF(Parametre_2018!I$4<>"",IF(N5<=Parametre_2018!I$4,IF(Parametre_2018!J$4<>"",IF(O5<=Parametre_2018!J$4,"CL",""),"CL"),""),IF(Parametre_2018!J$4<>"",IF(O5<=Parametre_2018!J$4,"CL",""),"CL"))),"MCL"),IF(Parametre_2018!I$4<>"",IF(N5<=Parametre_2018!I$4,IF(Parametre_2018!J$4<>"",IF(O5<=Parametre_2018!J$4,"CL",""),"CL"),""),IF(Parametre_2018!J$4<>"",IF(O5<=Parametre_2018!J$4,"CL",""),"CL"))),IF(Parametre_2018!D$4<>"",IF(O5<=Parametre_2018!D$4,"MCL",IF(Parametre_2018!I$4<>"",IF(N5<=Parametre_2018!I$4,IF(Parametre_2018!J$4<>"",IF(O5<=Parametre_2018!J$4,"CL",""),"CL"),""),IF(Parametre_2018!J$4<>"",IF(O5<=Parametre_2018!J$4,"CL",""),"CL"))),"MCL")),IF(Q5<>"",IF(AND(Q5>Parametre_2018!B$4,Q5<=Parametre_2018!H$4),IF(Parametre_2018!I$4<>"",IF(N5<=Parametre_2018!I$4,IF(Parametre_2018!J$4<>"",IF(O5<=Parametre_2018!J$4,"CL",""),"CL"),""),IF(Parametre_2018!J$4<>"",IF(O5<=Parametre_2018!J$4,"CL",""),"CL")),""),"")),"") -> CL | AE5: IT Spy
A6: 26 | B6: A | C6: Dragúňová | D6: Mária | E6: Bc. | F6: IS 2 | G6: 43262 | H6: 1p-IS | I6: Bieliková | J6: Pecár | K6: Identifikovanie charakteristík používateľa využitím analýzy pohľadu | L6: Mgr. Jozef Tvarožek, PhD. | M6: Ing. Jakub Šimko, PhD. | N6: A | O6: A | P6: 1.23 | Q6: 1.22 | U6: =IF(OR(V6<>"",Y6<>"",AB6<>""),"Navrh","") -> Navrh | W6: A | Y6: =IF(Q6<>"",IF(Q6<=1.2,IF(O6="A","CR",IF(V6<>"",IF(Parametre_2018!N$4=1,IF(LEFT(V6,1)="1",IF(V6<>"",IF(Parametre_2018!O$4<>"",IF(N6<=Parametre_2018!O$4,IF(V6<>"",IF(Parametre_2018!P$4<>"",IF(O6<=Parametre_2018!P$4,"PLD",""),"PLD"),""),""),IF(V6<>"",IF(Parametre_2018!P$4<>"",IF(O6<=Parametre_2018!P$4,"PLD",""),"PLD"),"")),""),""),IF(V6<>"",IF(Parametre_2018!O$4<>"",IF(N6<=Parametre_2018!O$4,IF(V6<>"",IF(Parametre_2018!P$4<>"",IF(O6<=Parametre_2018!P$4,"PLD",""),"PLD"),""),""),IF(V6<>"",IF(Parametre_2018!P$4<>"",IF(O6<=Parametre_2018!P$4,"PLD",""),"PLD"),"")),"")),"")),IF(V6<>"",IF(Parametre_2018!N$4=1,IF(LEFT(V6,1)="1",IF(V6<>"",IF(Parametre_2018!O$4<>"",IF(N6<=Parametre_2018!O$4,IF(V6<>"",IF(Parametre_2018!P$4<>"",IF(O6<=Parametre_2018!P$4,"PLD",""),"PLD"),""),""),IF(V6<>"",IF(Parametre_2018!P$4<>"",IF(O6<=Parametre_2018!P$4,"PLD",""),"PLD"),"")),""),""),IF(V6<>"",IF(Parametre_2018!O$4<>"",IF(N6<=Parametre_2018!O$4,IF(V6<>"",IF(Parametre_2018!P$4<>"",IF(O6<=Parametre_2018!P$4,"PLD",""),"PLD"),""),""),IF(V6<>"",IF(Parametre_2018!P$4<>"",IF(O6<=Parametre_2018!P$4,"PLD",""),"PLD"),"")),"")),"")),"") | Z6: CD? | AA6: IET | AB6: =IF(Q6<>"",IF(Q6<=Parametre_2018!B$4,IF(Parametre_2018!C$4<>"",IF(N6<=Parametre_2018!C$4,IF(Parametre_2018!D$4<>"",IF(O6<=Parametre_2018!D$4,"MCL",IF(Parametre_2018!I$4<>"",IF(N6<=Parametre_2018!I$4,IF(Parametre_2018!J$4<>"",IF(O6<=Parametre_2018!J$4,"CL",""),"CL"),""),IF(Parametre_2018!J$4<>"",IF(O6<=Parametre_2018!J$4,"CL",""),"CL"))),"MCL"),IF(Parametre_2018!I$4<>"",IF(N6<=Parametre_2018!I$4,IF(Parametre_2018!J$4<>"",IF(O6<=Parametre_2018!J$4,"CL",""),"CL"),""),IF(Parametre_2018!J$4<>"",IF(O6<=Parametre_2018!J$4,"CL",""),"CL"))),IF(Parametre_2018!D$4<>"",IF(O6<=Parametre_2018!D$4,"MCL",IF(Parametre_2018!I$4<>"",IF(N6<=Parametre_2018!I$4,IF(Parametre_2018!J$4<>"",IF(O6<=Parametre_2018!J$4,"CL",""),"CL"),""),IF(Parametre_2018!J$4<>"",IF(O6<=Parametre_2018!J$4,"CL",""),"CL"))),"MCL")),IF(Q6<>"",IF(AND(Q6>Parametre_2018!B$4,Q6<=Parametre_2018!H$4),IF(Parametre_2018!I$4<>"",IF(N6<=Parametre_2018!I$4,IF(Parametre_2018!J$4<>"",IF(O6<=Parametre_2018!J$4,"CL",""),"CL"),""),IF(Parametre_2018!J$4<>"",IF(O6<=Parametre_2018!J$4,"CL",""),"CL")),""),"")),"") -> CL
A7: 9 | B7: A | C7: Bobotová | D7: Zuzana | E7: Bc. | F7: IS 2 | G7: 43262 | H7: 7p-IS-SI | I7: Benešová | J7: Marták | K7: Spracovanie trojrozmerných medicínskych dát metódami počítačového videnia | L7: doc. Ing. Vanda Benešová, PhD. | M7: Ing. Martin Tamajka | N7: A | O7: A | P7: 1.4 | Q7: 1.3 | S7: A | U7: =IF(OR(V7<>"",Y7<>"",AB7<>""),"Navrh","") -> Navrh | V7: 2 | Y7: =IF(Q7<>"",IF(Q7<=1.2,IF(O7="A","CR",IF(V7<>"",IF(Parametre_2018!N$4=1,IF(LEFT(V7,1)="1",IF(V7<>"",IF(Parametre_2018!O$4<>"",IF(N7<=Parametre_2018!O$4,IF(V7<>"",IF(Parametre_2018!P$4<>"",IF(O7<=Parametre_2018!P$4,"PLD",""),"PLD"),""),""),IF(V7<>"",IF(Parametre_2018!P$4<>"",IF(O7<=Parametre_2018!P$4,"PLD",""),"PLD"),"")),""),""),IF(V7<>"",IF(Parametre_2018!O$4<>"",IF(N7<=Parametre_2018!O$4,IF(V7<>"",IF(Parametre_2018!P$4<>"",IF(O7<=Parametre_2018!P$4,"PLD",""),"PLD"),""),""),IF(V7<>"",IF(Parametre_2018!P$4<>"",IF(O7<=Parametre_2018!P$4,"PLD",""),"PLD"),"")),"")),"")),IF(V7<>"",IF(Parametre_2018!N$4=1,IF(LEFT(V7,1)="1",IF(V7<>"",IF(Parametre_2018!O$4<>"",IF(N7<=Parametre_2018!O$4,IF(V7<>"",IF(Parametre_2018!P$4<>"",IF(O7<=Parametre_2018!P$4,"PLD",""),"PLD"),""),""),IF(V7<>"",IF(Parametre_2018!P$4<>"",IF(O7<=Parametre_2018!P$4,"PLD",""),"PLD"),"")),""),""),IF(V7<>"",IF(Parametre_2018!O$4<>"",IF(N7<=Parametre_2018!O$4,IF(V7<>"",IF(Parametre_2018!P$4<>"",IF(O7<=Parametre_2018!P$4,"PLD",""),"PLD"),""),""),IF(V7<>"",IF(Parametre_2018!P$4<>"",IF(O7<=Parametre_2018!P$4,"PLD",""),"PLD"),"")),"")),"")),"") -> PLD | Z7: CD? | AA7: CD | AB7: =IF(Q7<>"",IF(Q7<=Parametre_2018!B$4,IF(Parametre_2018!C$4<>"",IF(N7<=Parametre_2018!C$4,IF(Parametre_2018!D$4<>"",IF(O7<=Parametre_2018!D$4,"MCL",IF(Parametre_2018!I$4<>"",IF(N7<=Parametre_2018!I$4,IF(Parametre_2018!J$4<>"",IF(O7<=Parametre_2018!J$4,"CL",""),"CL"),""),IF(Parametre_2018!J$4<>"",IF(O7<=Parametre_2018!J$4,"CL",""),"CL"))),"MCL"),IF(Parametre_2018!I$4<>"",IF(N7<=Parametre_2018!I$4,IF(Parametre_2018!J$4<>"",IF(O7<=Parametre_2018!J$4,"CL",""),"CL"),""),IF(Parametre_2018!J$4<>"",IF(O7<=Parametre_2018!J$4,"CL",""),"CL"))),IF(Parametre_2018!D$4<>"",IF(O7<=Parametre_2018!D$4,"MCL",IF(Parametre_2018!I$4<>"",IF(N7<=Parametre_2018!I$4,IF(Parametre_2018!J$4<>"",IF(O7<=Parametre_2018!J$4,"CL",""),"CL"),""),IF(Parametre_2018!J$4<>"",IF(O7<=Parametre_2018!J$4,"CL",""),"CL"))),"MCL")),IF(Q7<>"",IF(AND(Q7>Parametre_2018!B$4,Q7<=Parametre_2018!H$4),IF(Parametre_2018!I$4<>"",IF(N7<=Parametre_2018!I$4,IF(Parametre_2018!J$4<>"",IF(O7<=Parametre_2018!J$4,"CL",""),"CL"),""),IF(Parametre_2018!J$4<>"",IF(O7<=Parametre_2018!J$4,"CL",""),"CL")),""),"")),"") -> CL | AE7: IT Spy
A8: 70 | B8: A | C8: Mocko | D8: Martin | E8: Bc. | F8: IS 2 | G8: 43262 | H8: 1p-IS | I8: Bieliková | J8: Pecár | K8: Detekcia anomálií v transakčných údajoch | L8: Ing. Jakub Ševcech, PhD. | M8: Ing. Ondrej Kaššák, PhD. | N8: A | O8: A | P8: 1.38 | Q8: 1.3 | R8: D-IIS | U8: =IF(OR(V8<>"",Y8<>"",AB8<>""),"Navrh","") -> Navrh | W8: A | Y8: =IF(Q8<>"",IF(Q8<=1.2,IF(O8="A","CR",IF(V8<>"",IF(Parametre_2018!N$4=1,IF(LEFT(V8,1)="1",IF(V8<>"",IF(Parametre_2018!O$4<>"",IF(N8<=Parametre_2018!O$4,IF(V8<>"",IF(Parametre_2018!P$4<>"",IF(O8<=Parametre_2018!P$4,"PLD",""),"PLD"),""),""),IF(V8<>"",IF(Parametre_2018!P$4<>"",IF(O8<=Parametre_2018!P$4,"PLD",""),"PLD"),"")),""),""),IF(V8<>"",IF(Parametre_2018!O$4<>"",IF(N8<=Parametre_2018!O$4,IF(V8<>"",IF(Parametre_2018!P$4<>"",IF(O8<=Parametre_2018!P$4,"PLD",""),"PLD"),""),""),IF(V8<>"",IF(Parametre_2018!P$4<>"",IF(O8<=Parametre_2018!P$4,"PLD",""),"PLD"),"")),"")),"")),IF(V8<>"",IF(Parametre_2018!N$4=1,IF(LEFT(V8,1)="1",IF(V8<>"",IF(Parametre_2018!O$4<>"",IF(N8<=Parametre_2018!O$4,IF(V8<>"",IF(Parametre_2018!P$4<>"",IF(O8<=Parametre_2018!P$4,"PLD",""),"PLD"),""),""),IF(V8<>"",IF(Parametre_2018!P$4<>"",IF(O8<=Parametre_2018!P$4,"PLD",""),"PLD"),"")),""),""),IF(V8<>"",IF(Parametre_2018!O$4<>"",IF(N8<=Parametre_2018!O$4,IF(V8<>"",IF(Parametre_2018!P$4<>"",IF(O8<=Parametre_2018!P$4,"PLD",""),"PLD"),""),""),IF(V8<>"",IF(Parametre_2018!P$4<>"",IF(O8<=Parametre_2018!P$4,"PLD",""),"PLD"),"")),"")),"")),"") | Z8: CD/UI SAV | AA8: UI SAV | AB8: =IF(Q8<>"",IF(Q8<=Parametre_2018!B$4,IF(Parametre_2018!C$4<>"",IF(N8<=Parametre_2018!C$4,IF(Parametre_2018!D$4<>"",IF(O8<=Parametre_2018!D$4,"MCL",IF(Parametre_2018!I$4<>"",IF(N8<=Parametre_2018!I$4,IF(Parametre_2018!J$4<>"",IF(O8<=Parametre_2018!J$4,"CL",""),"CL"),""),IF(Parametre_2018!J$4<>"",IF(O8<=Parametre_2018!J$4,"CL",""),"CL"))),"MCL"),IF(Parametre_2018!I$4<>"",IF(N8<=Parametre_2018!I$4,IF(Parametre_2018!J$4<>"",IF(O8<=Parametre_2018!J$4,"CL",""),"CL"),""),IF(Parametre_2018!J$4<>"",IF(O8<=Parametre_2018!J$4,"CL",""),"CL"))),IF(Parametre_2018!D$4<>"",IF(O8<=Parametre_2018!D$4,"MCL",IF(Parametre_2018!I$4<>"",IF(N8<=Parametre_2018!I$4,IF(Parametre_2018!J$4<>"",IF(O8<=Parametre_2018!J$4,"CL",""),"CL"),""),IF(Parametre_2018!J$4<>"",IF(O8<=Parametre_2018!J$4,"CL",""),"CL"))),"MCL")),IF(Q8<>"",IF(AND(Q8>Parametre_2018!B$4,Q8<=Parametre_2018!H$4),IF(Parametre_2018!I$4<>"",IF(N8<=Parametre_2018!I$4,IF(Parametre_2018!J$4<>"",IF(O8<=Parametre_2018!J$4,"CL",""),"CL"),""),IF(Parametre_2018!J$4<>"",IF(O8<=Parametre_2018!J$4,"CL",""),"CL")),""),"")),"") -> CL
A9: 105 | B9: N | C9: Švec | D9: Andrej | E9: Bc. | F9: IS 2 | G9: 43262 | H9: 1p-IS | I9: Bieliková | J9: Pecár | K9: Modelovanie vhodnosti textových príspevkov | L9: prof. Ing. Mária Bieliková, PhD. | M9: doc. Ing. Marián Šimko, PhD. | N9: B | O9: A | P9: 1.35 | Q9: 1.32 | U9: =IF(OR(V9<>"",Y9<>"",AB9<>""),"Navrh","") -> Navrh | X9: A | Y9: =IF(Q9<>"",IF(Q9<=1.2,IF(O9="A","CR",IF(V9<>"",IF(Parametre_2018!N$4=1,IF(LEFT(V9,1)="1",IF(V9<>"",IF(Parametre_2018!O$4<>"",IF(N9<=Parametre_2018!O$4,IF(V9<>"",IF(Parametre_2018!P$4<>"",IF(O9<=Parametre_2018!P$4,"PLD",""),"PLD"),""),""),IF(V9<>"",IF(Parametre_2018!P$4<>"",IF(O9<=Parametre_2018!P$4,"PLD",""),"PLD"),"")),""),""),IF(V9<>"",IF(Parametre_2018!O$4<>"",IF(N9<=Parametre_2018!O$4,IF(V9<>"",IF(Parametre_2018!P$4<>"",IF(O9<=Parametre_2018!P$4,"PLD",""),"PLD"),""),""),IF(V9<>"",IF(Parametre_2018!P$4<>"",IF(O9<=Parametre_2018!P$4,"PLD",""),"PLD"),"")),"")),"")),IF(V9<>"",IF(Parametre_2018!N$4=1,IF(LEFT(V9,1)="1",IF(V9<>"",IF(Parametre_2018!O$4<>"",IF(N9<=Parametre_2018!O$4,IF(V9<>"",IF(Parametre_2018!P$4<>"",IF(O9<=Parametre_2018!P$4,"PLD",""),"PLD"),""),""),IF(V9<>"",IF(Parametre_2018!P$4<>"",IF(O9<=Parametre_2018!P$4,"PLD",""),"PLD"),"")),""),""),IF(V9<>"",IF(Parametre_2018!O$4<>"",IF(N9<=Parametre_2018!O$4,IF(V9<>"",IF(Parametre_2018!P$4<>"",IF(O9<=Parametre_2018!P$4,"PLD",""),"PLD"),""),""),IF(V9<>"",IF(Parametre_2018!P$4<>"",IF(O9<=Parametre_2018!P$4,"PLD",""),"PLD"),"")),"")),"")),"") | AB9: =IF(Q9<>"",IF(Q9<=Parametre_2018!B$4,IF(Parametre_2018!C$4<>"",IF(N9<=Parametre_2018!C$4,IF(Parametre_2018!D$4<>"",IF(O9<=Parametre_2018!D$4,"MCL",IF(Parametre_2018!I$4<>"",IF(N9<=Parametre_2018!I$4,IF(Parametre_2018!J$4<>"",IF(O9<=Parametre_2018!J$4,"CL",""),"CL"),""),IF(Parametre_2018!J$4<>"",IF(O9<=Parametre_2018!J$4,"CL",""),"CL"))),"MCL"),IF(Parametre_2018!I$4<>"",IF(N9<=Parametre_2018!I$4,IF(Parametre_2018!J$4<>"",IF(O9<=Parametre_2018!J$4,"CL",""),"CL"),""),IF(Parametre_2018!J$4<>"",IF(O9<=Parametre_2018!J$4,"CL",""),"CL"))),IF(Parametre_2018!D$4<>"",IF(O9<=Parametre_2018!D$4,"MCL",IF(Parametre_2018!I$4<>"",IF(N9<=Parametre_2018!I$4,IF(Parametre_2018!J$4<>"",IF(O9<=Parametre_2018!J$4,"CL",""),"CL"),""),IF(Parametre_2018!J$4<>"",IF(O9<=Parametre_2018!J$4,"CL",""),"CL"))),"MCL")),IF(Q9<>"",IF(AND(Q9>Parametre_2018!B$4,Q9<=Parametre_2018!H$4),IF(Parametre_2018!I$4<>"",IF(N9<=Parametre_2018!I$4,IF(Parametre_2018!J$4<>"",IF(O9<=Parametre_2018!J$4,"CL",""),"CL"),""),IF(Parametre_2018!J$4<>"",IF(O9<=Parametre_2018!J$4,"CL",""),"CL")),""),"")),"") -> CL
A10: 61 | B10: A | C10: Laco | D10: Miroslav | E10: Bc. | F10: IS 2 | G10: 43262 | H10: 7p-IS-SI | I10: Benešová | J10: Marták | K10: Model predikcie ľudskej vizuálnej pozornosti so zameraním na rôzne aspekty vizuálneho vnemu človeka | L10: doc. Ing. Vanda Benešová, PhD. | M10: Ing. Patrik Polatsek | N10: A | O10: A | P10: 1.39 | Q10: 1.33 | R10: D-AI | S10: A | U10: =IF(OR(V10<>"",Y10<>"",AB10<>""),"Navrh","") -> Navrh | V10: 1 | W10: A | X10: A | Y10: =IF(Q10<>"",IF(Q10<=1.2,IF(O10="A","CR",IF(V10<>"",IF(Parametre_2018!N$4=1,IF(LEFT(V10,1)="1",IF(V10<>"",IF(Parametre_2018!O$4<>"",IF(N10<=Parametre_2018!O$4,IF(V10<>"",IF(Parametre_2018!P$4<>"",IF(O10<=Parametre_2018!P$4,"PLD",""),"PLD"),""),""),IF(V10<>"",IF(Parametre_2018!P$4<>"",IF(O10<=Parametre_2018!P$4,"PLD",""),"PLD"),"")),""),""),IF(V10<>"",IF(Parametre_2018!O$4<>"",IF(N10<=Parametre_2018!O$4,IF(V10<>"",IF(Parametre_2018!P$4<>"",IF(O10<=Parametre_2018!P$4,"PLD",""),"PLD"),""),""),IF(V10<>"",IF(Parametre_2018!P$4<>"",IF(O10<=Parametre_2018!P$4,"PLD",""),"PLD"),"")),"")),"")),IF(V10<>"",IF(Parametre_2018!N$4=1,IF(LEFT(V10,1)="1",IF(V10<>"",IF(Parametre_2018!O$4<>"",IF(N10<=Parametre_2018!O$4,IF(V10<>"",IF(Parametre_2018!P$4<>"",IF(O10<=Parametre_2018!P$4,"PLD",""),"PLD"),""),""),IF(V10<>"",IF(Parametre_2018!P$4<>"",IF(O10<=Parametre_2018!P$4,"PLD",""),"PLD"),"")),""),""),IF(V10<>"",IF(Parametre_2018!O$4<>"",IF(N10<=Parametre_2018!O$4,IF(V10<>"",IF(Parametre_2018!P$4<>"",IF(O10<=Parametre_2018!P$4,"PLD",""),"PLD"),""),""),IF(V10<>"",IF(Parametre_2018!P$4<>"",IF(O10<=Parametre_2018!P$4,"PLD",""),"PLD"),"")),"")),"")),"") -> PLD | Z10: CD | AA10: CD | AB10: =IF(Q10<>"",IF(Q10<=Parametre_2018!B$4,IF(Parametre_2018!C$4<>"",IF(N10<=Parametre_2018!C$4,IF(Parametre_2018!D$4<>"",IF(O10<=Parametre_2018!D$4,"MCL",IF(Parametre_2018!I$4<>"",IF(N10<=Parametre_2018!I$4,IF(Parametre_2018!J$4<>"",IF(O10<=Parametre_2018!J$4,"CL",""),"CL"),""),IF(Parametre_2018!J$4<>"",IF(O10<=Parametre_2018!J$4,"CL",""),"CL"))),"MCL"),IF(Parametre_2018!I$4<>"",IF(N10<=Parametre_2018!I$4,IF(Parametre_2018!J$4<>"",IF(O10<=Parametre_2018!J$4,"CL",""),"CL"),""),IF(Parametre_2018!J$4<>"",IF(O10<=Parametre_2018!J$4,"CL",""),"CL"))),IF(Parametre_2018!D$4<>"",IF(O10<=Parametre_2018!D$4,"MCL",IF(Parametre_2018!I$4<>"",IF(N10<=Parametre_2018!I$4,IF(Parametre_2018!J$4<>"",IF(O10<=Parametre_2018!J$4,"CL",""),"CL"),""),IF(Parametre_2018!J$4<>"",IF(O10<=Parametre_2018!J$4,"CL",""),"CL"))),"MCL")),IF(Q10<>"",IF(AND(Q10>Parametre_2018!B$4,Q10<=Parametre_2018!H$4),IF(Parametre_2018!I$4<>"",IF(N10<=Parametre_2018!I$4,IF(Parametre_2018!J$4<>"",IF(O10<=Parametre_2018!J$4,"CL",""),"CL"),""),IF(Parametre_2018!J$4<>"",IF(O10<=Parametre_2018!J$4,"CL",""),"CL")),""),"")),"") -> CL | AE10: IT Spy
A11: 76 | B11: A | C11: Olejár | D11: Martin | E11: Bc. | F11: SI 2 | G11: 43263 | H11: 2u-SI | I11: Návrat | J11: Vincúr | K11: Detekcia sémantických konfliktov v softvérových modeloch | L11: Ing. Karol Rástočný, PhD. | M11: doc. Ing. Ivan Polášek, PhD. | N11: B | O11: A | P11: 1.35 | Q11: 1.35 | U11: =IF(OR(V11<>"",Y11<>"",AB11<>""),"Navrh","") -> Navrh | V11: 2 | W11: A | X11: A | Y11: =IF(Q11<>"",IF(Q11<=1.2,IF(O11="A","CR",IF(V11<>"",IF(Parametre_2018!N$4=1,IF(LEFT(V11,1)="1",IF(V11<>"",IF(Parametre_2018!O$4<>"",IF(N11<=Parametre_2018!O$4,IF(V11<>"",IF(Parametre_2018!P$4<>"",IF(O11<=Parametre_2018!P$4,"PLD",""),"PLD"),""),""),IF(V11<>"",IF(Parametre_2018!P$4<>"",IF(O11<=Parametre_2018!P$4,"PLD",""),"PLD"),"")),""),""),IF(V11<>"",IF(Parametre_2018!O$4<>"",IF(N11<=Parametre_2018!O$4,IF(V11<>"",IF(Parametre_2018!P$4<>"",IF(O11<=Parametre_2018!P$4,"PLD",""),"PLD"),""),""),IF(V11<>"",IF(Parametre_2018!P$4<>"",IF(O11<=Parametre_2018!P$4,"PLD",""),"PLD"),"")),"")),"")),IF(V11<>"",IF(Parametre_2018!N$4=1,IF(LEFT(V11,1)="1",IF(V11<>"",IF(Parametre_2018!O$4<>"",IF(N11<=Parametre_2018!O$4,IF(V11<>"",IF(Parametre_2018!P$4<>"",IF(O11<=Parametre_2018!P$4,"PLD",""),"PLD"),""),""),IF(V11<>"",IF(Parametre_2018!P$4<>"",IF(O11<=Parametre_2018!P$4,"PLD",""),"PLD"),"")),""),""),IF(V11<>"",IF(Parametre_2018!O$4<>"",IF(N11<=Parametre_2018!O$4,IF(V11<>"",IF(Parametre_2018!P$4<>"",IF(O11<=Parametre_2018!P$4,"PLD",""),"PLD"),""),""),IF(V11<>"",IF(Parametre_2018!P$4<>"",IF(O11<=Parametre_2018!P$4,"PLD",""),"PLD"),"")),"")),"")),"") -> PLD | Z11: CD/IET | AA11: CD | AB11: =IF(Q11<>"",IF(Q11<=Parametre_2018!B$4,IF(Parametre_2018!C$4<>"",IF(N11<=Parametre_2018!C$4,IF(Parametre_2018!D$4<>"",IF(O11<=Parametre_2018!D$4,"MCL",IF(Parametre_2018!I$4<>"",IF(N11<=Parametre_2018!I$4,IF(Parametre_2018!J$4<>"",IF(O11<=Parametre_2018!J$4,"CL",""),"CL"),""),IF(Parametre_2018!J$4<>"",IF(O11<=Parametre_2018!J$4,"CL",""),"CL"))),"MCL"),IF(Parametre_2018!I$4<>"",IF(N11<=Parametre_2018!I$4,IF(Parametre_2018!J$4<>"",IF(O11<=Parametre_2018!J$4,"CL",""),"CL"),""),IF(Parametre_2018!J$4<>"",IF(O11<=Parametre_2018!J$4,"CL",""),"CL"))),IF(Parametre_2018!D$4<>"",IF(O11<=Parametre_2018!D$4,"MCL",IF(Parametre_2018!I$4<>"",IF(N11<=Parametre_2018!I$4,IF(Parametre_2018!J$4<>"",IF(O11<=Parametre_2018!J$4,"CL",""),"CL"),""),IF(Parametre_2018!J$4<>"",IF(O11<=Parametre_2018!J$4,"CL",""),"CL"))),"MCL")),IF(Q11<>"",IF(AND(Q11>Parametre_2018!B$4,Q11<=Parametre_2018!H$4),IF(Parametre_2018!I$4<>"",IF(N11<=Parametre_2018!I$4,IF(Parametre_2018!J$4<>"",IF(O11<=Parametre_2018!J$4,"CL",""),"CL"),""),IF(Parametre_2018!J$4<>"",IF(O11<=Parametre_2018!J$4,"CL",""),"CL")),""),"")),"") -> CL | AE11: IT Spy
A12: 24 | B12: A | C12: Danišik | D12: Norbert | E12: Bc. | F12: SI 2 | G12: 43263 | H12: 3u-IS-SI | I12: Lucká | J12: Loebl | K12: Spracovanie veľkých objemov dát získaných športovou aktivitou | L12: doc. Ing. Peter Lacko, PhD. | M12: Ing. Michal Barla, PhD. | N12: A | O12: A | P12: 1.44 | Q12: 1.37 | S12: A | U12: =IF(OR(V12<>"",Y12<>"",AB12<>""),"Navrh","") -> Navrh | V12: 2(3) | W12: A | Y12: =IF(Q12<>"",IF(Q12<=1.2,IF(O12="A","CR",IF(V12<>"",IF(Parametre_2018!N$4=1,IF(LEFT(V12,1)="1",IF(V12<>"",IF(Parametre_2018!O$4<>"",IF(N12<=Parametre_2018!O$4,IF(V12<>"",IF(Parametre_2018!P$4<>"",IF(O12<=Parametre_2018!P$4,"PLD",""),"PLD"),""),""),IF(V12<>"",IF(Parametre_2018!P$4<>"",IF(O12<=Parametre_2018!P$4,"PLD",""),"PLD"),"")),""),""),IF(V12<>"",IF(Parametre_2018!O$4<>"",IF(N12<=Parametre_2018!O$4,IF(V12<>"",IF(Parametre_2018!P$4<>"",IF(O12<=Parametre_2018!P$4,"PLD",""),"PLD"),""),""),IF(V12<>"",IF(Parametre_2018!P$4<>"",IF(O12<=Parametre_2018!P$4,"PLD",""),"PLD"),"")),"")),"")),IF(V12<>"",IF(Parametre_2018!N$4=1,IF(LEFT(V12,1)="1",IF(V12<>"",IF(Parametre_2018!O$4<>"",IF(N12<=Parametre_2018!O$4,IF(V12<>"",IF(Parametre_2018!P$4<>"",IF(O12<=Parametre_2018!P$4,"PLD",""),"PLD"),""),""),IF(V12<>"",IF(Parametre_2018!P$4<>"",IF(O12<=Parametre_2018!P$4,"PLD",""),"PLD"),"")),""),""),IF(V12<>"",IF(Parametre_2018!O$4<>"",IF(N12<=Parametre_2018!O$4,IF(V12<>"",IF(Parametre_2018!P$4<>"",IF(O12<=Parametre_2018!P$4,"PLD",""),"PLD"),""),""),IF(V12<>"",IF(Parametre_2018!P$4<>"",IF(O12<=Parametre_2018!P$4,"PLD",""),"PLD"),"")),"")),"")),"") -> PLD | Z12: PLD | AA12: PLD | AB12: =IF(Q12<>"",IF(Q12<=Parametre_2018!B$4,IF(Parametre_2018!C$4<>"",IF(N12<=Parametre_2018!C$4,IF(Parametre_2018!D$4<>"",IF(O12<=Parametre_2018!D$4,"MCL",IF(Parametre_2018!I$4<>"",IF(N12<=Parametre_2018!I$4,IF(Parametre_2018!J$4<>"",IF(O12<=Parametre_2018!J$4,"CL",""),"CL"),""),IF(Parametre_2018!J$4<>"",IF(O12<=Parametre_2018!J$4,"CL",""),"CL"))),"MCL"),IF(Parametre_2018!I$4<>"",IF(N12<=Parametre_2018!I$4,IF(Parametre_2018!J$4<>"",IF(O12<=Parametre_2018!J$4,"CL",""),"CL"),""),IF(Parametre_2018!J$4<>"",IF(O12<=Parametre_2018!J$4,"CL",""),"CL"))),IF(Parametre_2018!D$4<>"",IF(O12<=Parametre_2018!D$4,"MCL",IF(Parametre_2018!I$4<>"",IF(N12<=Parametre_2018!I$4,IF(Parametre_2018!J$4<>"",IF(O12<=Parametre_2018!J$4,"CL",""),"CL"),""),IF(Parametre_2018!J$4<>"",IF(O12<=Parametre_2018!J$4,"CL",""),"CL"))),"MCL")),IF(Q12<>"",IF(AND(Q12>Parametre_2018!B$4,Q12<=Parametre_2018!H$4),IF(Parametre_2018!I$4<>"",IF(N12<=Parametre_2018!I$4,IF(Parametre_2018!J$4<>"",IF(O12<=Parametre_2018!J$4,"CL",""),"CL"),""),IF(Parametre_2018!J$4<>"",IF(O12<=Parametre_2018!J$4,"CL",""),"CL")),""),"")),"") -> CL
A13: 77 | B13: A | C13: Ondik | D13: Jakub | E13: Bc. | F13: SI 2 | G13: 43263 | H13: 2u-SI | I13: Návrat | J13: Vincúr | K13: Interaktívna vizualizácia zmien v softvérových modeloch | L13: Ing. Karol Rástočný, PhD. | M13: doc. Ing. Ivan Polášek, PhD. | N13: A | O13: A | P13: 1.42 | Q13: 1.38 | U13: =IF(OR(V13<>"",Y13<>"",AB13<>""),"Navrh","") -> Navrh | V13: 1 | W13: A | X13: A | Y13: =IF(Q13<>"",IF(Q13<=1.2,IF(O13="A","CR",IF(V13<>"",IF(Parametre_2018!N$4=1,IF(LEFT(V13,1)="1",IF(V13<>"",IF(Parametre_2018!O$4<>"",IF(N13<=Parametre_2018!O$4,IF(V13<>"",IF(Parametre_2018!P$4<>"",IF(O13<=Parametre_2018!P$4,"PLD",""),"PLD"),""),""),IF(V13<>"",IF(Parametre_2018!P$4<>"",IF(O13<=Parametre_2018!P$4,"PLD",""),"PLD"),"")),""),""),IF(V13<>"",IF(Parametre_2018!O$4<>"",IF(N13<=Parametre_2018!O$4,IF(V13<>"",IF(Parametre_2018!P$4<>"",IF(O13<=Parametre_2018!P$4,"PLD",""),"PLD"),""),""),IF(V13<>"",IF(Parametre_2018!P$4<>"",IF(O13<=Parametre_2018!P$4,"PLD",""),"PLD"),"")),"")),"")),IF(V13<>"",IF(Parametre_2018!N$4=1,IF(LEFT(V13,1)="1",IF(V13<>"",IF(Parametre_2018!O$4<>"",IF(N13<=Parametre_2018!O$4,IF(V13<>"",IF(Parametre_2018!P$4<>"",IF(O13<=Parametre_2018!P$4,"PLD",""),"PLD"),""),""),IF(V13<>"",IF(Parametre_2018!P$4<>"",IF(O13<=Parametre_2018!P$4,"PLD",""),"PLD"),"")),""),""),IF(V13<>"",IF(Parametre_2018!O$4<>"",IF(N13<=Parametre_2018!O$4,IF(V13<>"",IF(Parametre_2018!P$4<>"",IF(O13<=Parametre_2018!P$4,"PLD",""),"PLD"),""),""),IF(V13<>"",IF(Parametre_2018!P$4<>"",IF(O13<=Parametre_2018!P$4,"PLD",""),"PLD"),"")),"")),"")),"") -> PLD | Z13: PLD | AA13: P:LD | AB13: =IF(Q13<>"",IF(Q13<=Parametre_2018!B$4,IF(Parametre_2018!C$4<>"",IF(N13<=Parametre_2018!C$4,IF(Parametre_2018!D$4<>"",IF(O13<=Parametre_2018!D$4,"MCL",IF(Parametre_2018!I$4<>"",IF(N13<=Parametre_2018!I$4,IF(Parametre_2018!J$4<>"",IF(O13<=Parametre_2018!J$4,"CL",""),"CL"),""),IF(Parametre_2018!J$4<>"",IF(O13<=Parametre_2018!J$4,"CL",""),"CL"))),"MCL"),IF(Parametre_2018!I$4<>"",IF(N13<=Parametre_2018!I$4,IF(Parametre_2018!J$4<>"",IF(O13<=Parametre_2018!J$4,"CL",""),"CL"),""),IF(Parametre_2018!J$4<>"",IF(O13<=Parametre_2018!J$4,"CL",""),"CL"))),IF(Parametre_2018!D$4<>"",IF(O13<=Parametre_2018!D$4,"MCL",IF(Parametre_2018!I$4<>"",IF(N13<=Parametre_2018!I$4,IF(Parametre_2018!J$4<>"",IF(O13<=Parametre_2018!J$4,"CL",""),"CL"),""),IF(Parametre_2018!J$4<>"",IF(O13<=Parametre_2018!J$4,"CL",""),"CL"))),"MCL")),IF(Q13<>"",IF(AND(Q13>Parametre_2018!B$4,Q13<=Parametre_2018!H$4),IF(Parametre_2018!I$4<>"",IF(N13<=Parametre_2018!I$4,IF(Parametre_2018!J$4<>"",IF(O13<=Parametre_2018!J$4,"CL",""),"CL"),""),IF(Parametre_2018!J$4<>"",IF(O13<=Parametre_2018!J$4,"CL",""),"CL")),""),"")),"") -> CL | AE13: IT Spy
A14: 113 | B14: A | C14: Víťaz | D14: Matej | E14: Bc. | F14: IS 2 | G14: 43263 | H14: 1u-IS | I14: Bieliková | J14: Konôpka | K14: Automatická identifikácia problémov použiteľnosti na Webe z údajov pohľadu používateľa | L14: Ing. Eduard Kuric, PhD. | M14: Ing. Róbert Móro, PhD. | N14: B | O14: B | P14: 1.28 | Q14: 1.38 | U14: =IF(OR(V14<>"",Y14<>"",AB14<>""),"Navrh","") -> Navrh | W14: A | Y14: =IF(Q14<>"",IF(Q14<=1.2,IF(O14="A","CR",IF(V14<>"",IF(Parametre_2018!N$4=1,IF(LEFT(V14,1)="1",IF(V14<>"",IF(Parametre_2018!O$4<>"",IF(N14<=Parametre_2018!O$4,IF(V14<>"",IF(Parametre_2018!P$4<>"",IF(O14<=Parametre_2018!P$4,"PLD",""),"PLD"),""),""),IF(V14<>"",IF(Parametre_2018!P$4<>"",IF(O14<=Parametre_2018!P$4,"PLD",""),"PLD"),"")),""),""),IF(V14<>"",IF(Parametre_2018!O$4<>"",IF(N14<=Parametre_2018!O$4,IF(V14<>"",IF(Parametre_2018!P$4<>"",IF(O14<=Parametre_2018!P$4,"PLD",""),"PLD"),""),""),IF(V14<>"",IF(Parametre_2018!P$4<>"",IF(O14<=Parametre_2018!P$4,"PLD",""),"PLD"),"")),"")),"")),IF(V14<>"",IF(Parametre_2018!N$4=1,IF(LEFT(V14,1)="1",IF(V14<>"",IF(Parametre_2018!O$4<>"",IF(N14<=Parametre_2018!O$4,IF(V14<>"",IF(Parametre_2018!P$4<>"",IF(O14<=Parametre_2018!P$4,"PLD",""),"PLD"),""),""),IF(V14<>"",IF(Parametre_2018!P$4<>"",IF(O14<=Parametre_2018!P$4,"PLD",""),"PLD"),"")),""),""),IF(V14<>"",IF(Parametre_2018!O$4<>"",IF(N14<=Parametre_2018!O$4,IF(V14<>"",IF(Parametre_2018!P$4<>"",IF(O14<=Parametre_2018!P$4,"PLD",""),"PLD"),""),""),IF(V14<>"",IF(Parametre_2018!P$4<>"",IF(O14<=Parametre_2018!P$4,"PLD",""),"PLD"),"")),"")),"")),"") | AB14: =IF(Q14<>"",IF(Q14<=Parametre_2018!B$4,IF(Parametre_2018!C$4<>"",IF(N14<=Parametre_2018!C$4,IF(Parametre_2018!D$4<>"",IF(O14<=Parametre_2018!D$4,"MCL",IF(Parametre_2018!I$4<>"",IF(N14<=Parametre_2018!I$4,IF(Parametre_2018!J$4<>"",IF(O14<=Parametre_2018!J$4,"CL",""),"CL"),""),IF(Parametre_2018!J$4<>"",IF(O14<=Parametre_2018!J$4,"CL",""),"CL"))),"MCL"),IF(Parametre_2018!I$4<>"",IF(N14<=Parametre_2018!I$4,IF(Parametre_2018!J$4<>"",IF(O14<=Parametre_2018!J$4,"CL",""),"CL"),""),IF(Parametre_2018!J$4<>"",IF(O14<=Parametre_2018!J$4,"CL",""),"CL"))),IF(Parametre_2018!D$4<>"",IF(O14<=Parametre_2018!D$4,"MCL",IF(Parametre_2018!I$4<>"",IF(N14<=Parametre_2018!I$4,IF(Parametre_2018!J$4<>"",IF(O14<=Parametre_2018!J$4,"CL",""),"CL"),""),IF(Parametre_2018!J$4<>"",IF(O14<=Parametre_2018!J$4,"CL",""),"CL"))),"MCL")),IF(Q14<>"",IF(AND(Q14>Parametre_2018!B$4,Q14<=Parametre_2018!H$4),IF(Parametre_2018!I$4<>"",IF(N14<=Parametre_2018!I$4,IF(Parametre_2018!J$4<>"",IF(O14<=Parametre_2018!J$4,"CL",""),"CL"),""),IF(Parametre_2018!J$4<>"",IF(O14<=Parametre_2018!J$4,"CL",""),"CL")),""),"")),"") -> CL
A15: 54 | B15: A | C15: Kostova | D15: Sandra | E15: Bc. | F15: IS 2 | G15: 43262 | H15: 1p-IS | I15: Bieliková | J15: Pecár | K15: Automatické určovanie miery zvedavosti používateľa na základe jeho správania na webe | L15: Ing. Jakub Šimko, PhD. | M15: Ing. Ivan Srba, PhD. | N15: B | O15: A | P15: 1.4 | Q15: 1.39 | S15: A | U15: =IF(OR(V15<>"",Y15<>"",AB15<>""),"Navrh","") -> Navrh | X15: A | Y15: =IF(Q15<>"",IF(Q15<=1.2,IF(O15="A","CR",IF(V15<>"",IF(Parametre_2018!N$4=1,IF(LEFT(V15,1)="1",IF(V15<>"",IF(Parametre_2018!O$4<>"",IF(N15<=Parametre_2018!O$4,IF(V15<>"",IF(Parametre_2018!P$4<>"",IF(O15<=Parametre_2018!P$4,"PLD",""),"PLD"),""),""),IF(V15<>"",IF(Parametre_2018!P$4<>"",IF(O15<=Parametre_2018!P$4,"PLD",""),"PLD"),"")),""),""),IF(V15<>"",IF(Parametre_2018!O$4<>"",IF(N15<=Parametre_2018!O$4,IF(V15<>"",IF(Parametre_2018!P$4<>"",IF(O15<=Parametre_2018!P$4,"PLD",""),"PLD"),""),""),IF(V15<>"",IF(Parametre_2018!P$4<>"",IF(O15<=Parametre_2018!P$4,"PLD",""),"PLD"),"")),"")),"")),IF(V15<>"",IF(Parametre_2018!N$4=1,IF(LEFT(V15,1)="1",IF(V15<>"",IF(Parametre_2018!O$4<>"",IF(N15<=Parametre_2018!O$4,IF(V15<>"",IF(Parametre_2018!P$4<>"",IF(O15<=Parametre_2018!P$4,"PLD",""),"PLD"),""),""),IF(V15<>"",IF(Parametre_2018!P$4<>"",IF(O15<=Parametre_2018!P$4,"PLD",""),"PLD"),"")),""),""),IF(V15<>"",IF(Parametre_2018!O$4<>"",IF(N15<=Parametre_2018!O$4,IF(V15<>"",IF(Parametre_2018!P$4<>"",IF(O15<=Parametre_2018!P$4,"PLD",""),"PLD"),""),""),IF(V15<>"",IF(Parametre_2018!P$4<>"",IF(O15<=Parametre_2018!P$4,"PLD",""),"PLD"),"")),"")),"")),"") | AB15: =IF(Q15<>"",IF(Q15<=Parametre_2018!B$4,IF(Parametre_2018!C$4<>"",IF(N15<=Parametre_2018!C$4,IF(Parametre_2018!D$4<>"",IF(O15<=Parametre_2018!D$4,"MCL",IF(Parametre_2018!I$4<>"",IF(N15<=Parametre_2018!I$4,IF(Parametre_2018!J$4<>"",IF(O15<=Parametre_2018!J$4,"CL",""),"CL"),""),IF(Parametre_2018!J$4<>"",IF(O15<=Parametre_2018!J$4,"CL",""),"CL"))),"MCL"),IF(Parametre_2018!I$4<>"",IF(N15<=Parametre_2018!I$4,IF(Parametre_2018!J$4<>"",IF(O15<=Parametre_2018!J$4,"CL",""),"CL"),""),IF(Parametre_2018!J$4<>"",IF(O15<=Parametre_2018!J$4,"CL",""),"CL"))),IF(Parametre_2018!D$4<>"",IF(O15<=Parametre_2018!D$4,"MCL",IF(Parametre_2018!I$4<>"",IF(N15<=Parametre_2018!I$4,IF(Parametre_2018!J$4<>"",IF(O15<=Parametre_2018!J$4,"CL",""),"CL"),""),IF(Parametre_2018!J$4<>"",IF(O15<=Parametre_2018!J$4,"CL",""),"CL"))),"MCL")),IF(Q15<>"",IF(AND(Q15>Parametre_2018!B$4,Q15<=Parametre_2018!H$4),IF(Parametre_2018!I$4<>"",IF(N15<=Parametre_2018!I$4,IF(Parametre_2018!J$4<>"",IF(O15<=Parametre_2018!J$4,"CL",""),"CL"),""),IF(Parametre_2018!J$4<>"",IF(O15<=Parametre_2018!J$4,"CL",""),"CL")),""),"")),"") -> CL
A16: 94 | B16: A | C16: Salát | D16: Matúš | E16: Bc. | F16: IS 2 | G16: 43262 | H16: 4p-IS-SI | I16: Rozinajová | J16: Gašpar | K16: Segmentovanie používateľov pre personalizáciu informačných bulletinov v CQA systémoch | L16: Ing. Ivan Srba, PhD. | M16: Ing. Peter Gašpar | N16: A | O16: A | P16: 1.43 | Q16: 1.39 | U16: =IF(OR(V16<>"",Y16<>"",AB16<>""),"Navrh","") -> Navrh | V16: 1 | Y16: =IF(Q16<>"",IF(Q16<=1.2,IF(O16="A","CR",IF(V16<>"",IF(Parametre_2018!N$4=1,IF(LEFT(V16,1)="1",IF(V16<>"",IF(Parametre_2018!O$4<>"",IF(N16<=Parametre_2018!O$4,IF(V16<>"",IF(Parametre_2018!P$4<>"",IF(O16<=Parametre_2018!P$4,"PLD",""),"PLD"),""),""),IF(V16<>"",IF(Parametre_2018!P$4<>"",IF(O16<=Parametre_2018!P$4,"PLD",""),"PLD"),"")),""),""),IF(V16<>"",IF(Parametre_2018!O$4<>"",IF(N16<=Parametre_2018!O$4,IF(V16<>"",IF(Parametre_2018!P$4<>"",IF(O16<=Parametre_2018!P$4,"PLD",""),"PLD"),""),""),IF(V16<>"",IF(Parametre_2018!P$4<>"",IF(O16<=Parametre_2018!P$4,"PLD",""),"PLD"),"")),"")),"")),IF(V16<>"",IF(Parametre_2018!N$4=1,IF(LEFT(V16,1)="1",IF(V16<>"",IF(Parametre_2018!O$4<>"",IF(N16<=Parametre_2018!O$4,IF(V16<>"",IF(Parametre_2018!P$4<>"",IF(O16<=Parametre_2018!P$4,"PLD",""),"PLD"),""),""),IF(V16<>"",IF(Parametre_2018!P$4<>"",IF(O16<=Parametre_2018!P$4,"PLD",""),"PLD"),"")),""),""),IF(V16<>"",IF(Parametre_2018!O$4<>"",IF(N16<=Parametre_2018!O$4,IF(V16<>"",IF(Parametre_2018!P$4<>"",IF(O16<=Parametre_2018!P$4,"PLD",""),"PLD"),""),""),IF(V16<>"",IF(Parametre_2018!P$4<>"",IF(O16<=Parametre_2018!P$4,"PLD",""),"PLD"),"")),"")),"")),"") -> PLD | Z16: PLD | AA16: PLD | AB16: =IF(Q16<>"",IF(Q16<=Parametre_2018!B$4,IF(Parametre_2018!C$4<>"",IF(N16<=Parametre_2018!C$4,IF(Parametre_2018!D$4<>"",IF(O16<=Parametre_2018!D$4,"MCL",IF(Parametre_2018!I$4<>"",IF(N16<=Parametre_2018!I$4,IF(Parametre_2018!J$4<>"",IF(O16<=Parametre_2018!J$4,"CL",""),"CL"),""),IF(Parametre_2018!J$4<>"",IF(O16<=Parametre_2018!J$4,"CL",""),"CL"))),"MCL"),IF(Parametre_2018!I$4<>"",IF(N16<=Parametre_2018!I$4,IF(Parametre_2018!J$4<>"",IF(O16<=Parametre_2018!J$4,"CL",""),"CL"),""),IF(Parametre_2018!J$4<>"",IF(O16<=Parametre_2018!J$4,"CL",""),"CL"))),IF(Parametre_2018!D$4<>"",IF(O16<=Parametre_2018!D$4,"MCL",IF(Parametre_2018!I$4<>"",IF(N16<=Parametre_2018!I$4,IF(Parametre_2018!J$4<>"",IF(O16<=Parametre_2018!J$4,"CL",""),"CL"),""),IF(Parametre_2018!J$4<>"",IF(O16<=Parametre_2018!J$4,"CL",""),"CL"))),"MCL")),IF(Q16<>"",IF(AND(Q16>Parametre_2018!B$4,Q16<=Parametre_2018!H$4),IF(Parametre_2018!I$4<>"",IF(N16<=Parametre_2018!I$4,IF(Parametre_2018!J$4<>"",IF(O16<=Parametre_2018!J$4,"CL",""),"CL"),""),IF(Parametre_2018!J$4<>"",IF(O16<=Parametre_2018!J$4,"CL",""),"CL")),""),"")),"") -> CL
A17: 71 | B17: A | C17: Mokrý | D17: Martin | E17: Bc. | F17: IS 2 | G17: 43262 | H17: 4p-IS-SI | I17: Rozinajová | J17: Gašpar | K17: Identifikácia zručnosti používateľa na webe na základe vzorov zo sledovania pohľadu | L17: Ing. Róbert Móro, PhD. | M17: Ing. Jakub Šimko, PhD. | N17: A | O17: A | P17: 1.45 | Q17: 1.41 | U17: =IF(OR(V17<>"",Y17<>"",AB17<>""),"Navrh","") -> Navrh | V17: 2 | W17: A | X17: A | Y17: =IF(Q17<>"",IF(Q17<=1.2,IF(O17="A","CR",IF(V17<>"",IF(Parametre_2018!N$4=1,IF(LEFT(V17,1)="1",IF(V17<>"",IF(Parametre_2018!O$4<>"",IF(N17<=Parametre_2018!O$4,IF(V17<>"",IF(Parametre_2018!P$4<>"",IF(O17<=Parametre_2018!P$4,"PLD",""),"PLD"),""),""),IF(V17<>"",IF(Parametre_2018!P$4<>"",IF(O17<=Parametre_2018!P$4,"PLD",""),"PLD"),"")),""),""),IF(V17<>"",IF(Parametre_2018!O$4<>"",IF(N17<=Parametre_2018!O$4,IF(V17<>"",IF(Parametre_2018!P$4<>"",IF(O17<=Parametre_2018!P$4,"PLD",""),"PLD"),""),""),IF(V17<>"",IF(Parametre_2018!P$4<>"",IF(O17<=Parametre_2018!P$4,"PLD",""),"PLD"),"")),"")),"")),IF(V17<>"",IF(Parametre_2018!N$4=1,IF(LEFT(V17,1)="1",IF(V17<>"",IF(Parametre_2018!O$4<>"",IF(N17<=Parametre_2018!O$4,IF(V17<>"",IF(Parametre_2018!P$4<>"",IF(O17<=Parametre_2018!P$4,"PLD",""),"PLD"),""),""),IF(V17<>"",IF(Parametre_2018!P$4<>"",IF(O17<=Parametre_2018!P$4,"PLD",""),"PLD"),"")),""),""),IF(V17<>"",IF(Parametre_2018!O$4<>"",IF(N17<=Parametre_2018!O$4,IF(V17<>"",IF(Parametre_2018!P$4<>"",IF(O17<=Parametre_2018!P$4,"PLD",""),"PLD"),""),""),IF(V17<>"",IF(Parametre_2018!P$4<>"",IF(O17<=Parametre_2018!P$4,"PLD",""),"PLD"),"")),"")),"")),"") -> PLD | Z17: PLD | AA17: PLD | AB17: =IF(Q17<>"",IF(Q17<=Parametre_2018!B$4,IF(Parametre_2018!C$4<>"",IF(N17<=Parametre_2018!C$4,IF(Parametre_2018!D$4<>"",IF(O17<=Parametre_2018!D$4,"MCL",IF(Parametre_2018!I$4<>"",IF(N17<=Parametre_2018!I$4,IF(Parametre_2018!J$4<>"",IF(O17<=Parametre_2018!J$4,"CL",""),"CL"),""),IF(Parametre_2018!J$4<>"",IF(O17<=Parametre_2018!J$4,"CL",""),"CL"))),"MCL"),IF(Parametre_2018!I$4<>"",IF(N17<=Parametre_2018!I$4,IF(Parametre_2018!J$4<>"",IF(O17<=Parametre_2018!J$4,"CL",""),"CL"),""),IF(Parametre_2018!J$4<>"",IF(O17<=Parametre_2018!J$4,"CL",""),"CL"))),IF(Parametre_2018!D$4<>"",IF(O17<=Parametre_2018!D$4,"MCL",IF(Parametre_2018!I$4<>"",IF(N17<=Parametre_2018!I$4,IF(Parametre_2018!J$4<>"",IF(O17<=Parametre_2018!J$4,"CL",""),"CL"),""),IF(Parametre_2018!J$4<>"",IF(O17<=Parametre_2018!J$4,"CL",""),"CL"))),"MCL")),IF(Q17<>"",IF(AND(Q17>Parametre_2018!B$4,Q17<=Parametre_2018!H$4),IF(Parametre_2018!I$4<>"",IF(N17<=Parametre_2018!I$4,IF(Parametre_2018!J$4<>"",IF(O17<=Parametre_2018!J$4,"CL",""),"CL"),""),IF(Parametre_2018!J$4<>"",IF(O17<=Parametre_2018!J$4,"CL",""),"CL")),""),"")),"") | AE17: IT Spy
A18: 59 | B18: A | C18: Krchňavý | D18: Rastislav | E18: Bc. | F18: IS 2 | G18: 43263 | H18: 5u-IS | I18: Šimko | J18: Pikuliak | K18: Aspektovo orientovaná analýza sentimentu | L18: doc. Ing. Marián Šimko, PhD. | M18: Ing. Miroslav Blšták | N18: B | O18: A | P18: 1.47 | Q18: 1.42 | U18: =IF(OR(V18<>"",Y18<>"",AB18<>""),"Navrh","") | W18: A | X18: A | Y18: =IF(Q18<>"",IF(Q18<=1.2,IF(O18="A","CR",IF(V18<>"",IF(Parametre_2018!N$4=1,IF(LEFT(V18,1)="1",IF(V18<>"",IF(Parametre_2018!O$4<>"",IF(N18<=Parametre_2018!O$4,IF(V18<>"",IF(Parametre_2018!P$4<>"",IF(O18<=Parametre_2018!P$4,"PLD",""),"PLD"),""),""),IF(V18<>"",IF(Parametre_2018!P$4<>"",IF(O18<=Parametre_2018!P$4,"PLD",""),"PLD"),"")),""),""),IF(V18<>"",IF(Parametre_2018!O$4<>"",IF(N18<=Parametre_2018!O$4,IF(V18<>"",IF(Parametre_2018!P$4<>"",IF(O18<=Parametre_2018!P$4,"PLD",""),"PLD"),""),""),IF(V18<>"",IF(Parametre_2018!P$4<>"",IF(O18<=Parametre_2018!P$4,"PLD",""),"PLD"),"")),"")),"")),IF(V18<>"",IF(Parametre_2018!N$4=1,IF(LEFT(V18,1)="1",IF(V18<>"",IF(Parametre_2018!O$4<>"",IF(N18<=Parametre_2018!O$4,IF(V18<>"",IF(Parametre_2018!P$4<>"",IF(O18<=Parametre_2018!P$4,"PLD",""),"PLD"),""),""),IF(V18<>"",IF(Parametre_2018!P$4<>"",IF(O18<=Parametre_2018!P$4,"PLD",""),"PLD"),"")),""),""),IF(V18<>"",IF(Parametre_2018!O$4<>"",IF(N18<=Parametre_2018!O$4,IF(V18<>"",IF(Parametre_2018!P$4<>"",IF(O18<=Parametre_2018!P$4,"PLD",""),"PLD"),""),""),IF(V18<>"",IF(Parametre_2018!P$4<>"",IF(O18<=Parametre_2018!P$4,"PLD",""),"PLD"),"")),"")),"")),"") | AB18: =IF(Q18<>"",IF(Q18<=Parametre_2018!B$4,IF(Parametre_2018!C$4<>"",IF(N18<=Parametre_2018!C$4,IF(Parametre_2018!D$4<>"",IF(O18<=Parametre_2018!D$4,"MCL",IF(Parametre_2018!I$4<>"",IF(N18<=Parametre_2018!I$4,IF(Parametre_2018!J$4<>"",IF(O18<=Parametre_2018!J$4,"CL",""),"CL"),""),IF(Parametre_2018!J$4<>"",IF(O18<=Parametre_2018!J$4,"CL",""),"CL"))),"MCL"),IF(Parametre_2018!I$4<>"",IF(N18<=Parametre_2018!I$4,IF(Parametre_2018!J$4<>"",IF(O18<=Parametre_2018!J$4,"CL",""),"CL"),""),IF(Parametre_2018!J$4<>"",IF(O18<=Parametre_2018!J$4,"CL",""),"CL"))),IF(Parametre_2018!D$4<>"",IF(O18<=Parametre_2018!D$4,"MCL",IF(Parametre_2018!I$4<>"",IF(N18<=Parametre_2018!I$4,IF(Parametre_2018!J$4<>"",IF(O18<=Parametre_2018!J$4,"CL",""),"CL"),""),IF(Parametre_2018!J$4<>"",IF(O18<=Parametre_2018!J$4,"CL",""),"CL"))),"MCL")),IF(Q18<>"",IF(AND(Q18>Parametre_2018!B$4,Q18<=Parametre_2018!H$4),IF(Parametre_2018!I$4<>"",IF(N18<=Parametre_2018!I$4,IF(Parametre_2018!J$4<>"",IF(O18<=Parametre_2018!J$4,"CL",""),"CL"),""),IF(Parametre_2018!J$4<>"",IF(O18<=Parametre_2018!J$4,"CL",""),"CL")),""),"")),"")
A19: 74 | B19: A | C19: Nemček | D19: Martin | E19: Bc. | F19: IS 2 | G19: 43263 | H19: 3u-IS-SI | I19: Lucká | J19: Loebl | K19: Redukcia cytometrických dát na základe hustoty a predikcia stavu pacienta z klinických dát | L19: doc. RNDr. Mária Lucká, PhD. | M19: RNDr. Anna Bou Ezzeddine, PhD. | N19: A | O19: A | P19: 1.54 | Q19: 1.44 | U19: =IF(OR(V19<>"",Y19<>"",AB19<>""),"Navrh","") -> Navrh | V19: 1A | W19: A | X19: A | Y19: =IF(Q19<>"",IF(Q19<=1.2,IF(O19="A","CR",IF(V19<>"",IF(Parametre_2018!N$4=1,IF(LEFT(V19,1)="1",IF(V19<>"",IF(Parametre_2018!O$4<>"",IF(N19<=Parametre_2018!O$4,IF(V19<>"",IF(Parametre_2018!P$4<>"",IF(O19<=Parametre_2018!P$4,"PLD",""),"PLD"),""),""),IF(V19<>"",IF(Parametre_2018!P$4<>"",IF(O19<=Parametre_2018!P$4,"PLD",""),"PLD"),"")),""),""),IF(V19<>"",IF(Parametre_2018!O$4<>"",IF(N19<=Parametre_2018!O$4,IF(V19<>"",IF(Parametre_2018!P$4<>"",IF(O19<=Parametre_2018!P$4,"PLD",""),"PLD"),""),""),IF(V19<>"",IF(Parametre_2018!P$4<>"",IF(O19<=Parametre_2018!P$4,"PLD",""),"PLD"),"")),"")),"")),IF(V19<>"",IF(Parametre_2018!N$4=1,IF(LEFT(V19,1)="1",IF(V19<>"",IF(Parametre_2018!O$4<>"",IF(N19<=Parametre_2018!O$4,IF(V19<>"",IF(Parametre_2018!P$4<>"",IF(O19<=Parametre_2018!P$4,"PLD",""),"PLD"),""),""),IF(V19<>"",IF(Parametre_2018!P$4<>"",IF(O19<=Parametre_2018!P$4,"PLD",""),"PLD"),"")),""),""),IF(V19<>"",IF(Parametre_2018!O$4<>"",IF(N19<=Parametre_2018!O$4,IF(V19<>"",IF(Parametre_2018!P$4<>"",IF(O19<=Parametre_2018!P$4,"PLD",""),"PLD"),""),""),IF(V19<>"",IF(Parametre_2018!P$4<>"",IF(O19<=Parametre_2018!P$4,"PLD",""),"PLD"),"")),"")),"")),"") -> PLD | Z19: PLD | AA19: PLD | AB19: =IF(Q19<>"",IF(Q19<=Parametre_2018!B$4,IF(Parametre_2018!C$4<>"",IF(N19<=Parametre_2018!C$4,IF(Parametre_2018!D$4<>"",IF(O19<=Parametre_2018!D$4,"MCL",IF(Parametre_2018!I$4<>"",IF(N19<=Parametre_2018!I$4,IF(Parametre_2018!J$4<>"",IF(O19<=Parametre_2018!J$4,"CL",""),"CL"),""),IF(Parametre_2018!J$4<>"",IF(O19<=Parametre_2018!J$4,"CL",""),"CL"))),"MCL"),IF(Parametre_2018!I$4<>"",IF(N19<=Parametre_2018!I$4,IF(Parametre_2018!J$4<>"",IF(O19<=Parametre_2018!J$4,"CL",""),"CL"),""),IF(Parametre_2018!J$4<>"",IF(O19<=Parametre_2018!J$4,"CL",""),"CL"))),IF(Parametre_2018!D$4<>"",IF(O19<=Parametre_2018!D$4,"MCL",IF(Parametre_2018!I$4<>"",IF(N19<=Parametre_2018!I$4,IF(Parametre_2018!J$4<>"",IF(O19<=Parametre_2018!J$4,"CL",""),"CL"),""),IF(Parametre_2018!J$4<>"",IF(O19<=Parametre_2018!J$4,"CL",""),"CL"))),"MCL")),IF(Q19<>"",IF(AND(Q19>Parametre_2018!B$4,Q19<=Parametre_2018!H$4),IF(Parametre_2018!I$4<>"",IF(N19<=Parametre_2018!I$4,IF(Parametre_2018!J$4<>"",IF(O19<=Parametre_2018!J$4,"CL",""),"CL"),""),IF(Parametre_2018!J$4<>"",IF(O19<=Parametre_2018!J$4,"CL",""),"CL")),""),"")),"") | AE19: IT Spy
A20: 49 | B20: A | C20: Juhaniak | D20: Tomáš | E20: Bc. | F20: IS 2 | G20: 43262 | H20: 1p-IS | I20: Bieliková | J20: Pecár | K20: Vyhodnocovanie kognitívnej záťaže ako súčasť používateľských štúdií | L20: prof. Ing. Mária Bieliková, PhD. | M20: Ing. Róbert Móro, PhD. | N20: A | O20: A | P20: 1.53 | Q20: 1.47 | U20: =IF(OR(V20<>"",Y20<>"",AB20<>""),"Navrh","") -> Navrh | V20: 2 | W20: A | X20: A | Y20: =IF(Q20<>"",IF(Q20<=1.2,IF(O20="A","CR",IF(V20<>"",IF(Parametre_2018!N$4=1,IF(LEFT(V20,1)="1",IF(V20<>"",IF(Parametre_2018!O$4<>"",IF(N20<=Parametre_2018!O$4,IF(V20<>"",IF(Parametre_2018!P$4<>"",IF(O20<=Parametre_2018!P$4,"PLD",""),"PLD"),""),""),IF(V20<>"",IF(Parametre_2018!P$4<>"",IF(O20<=Parametre_2018!P$4,"PLD",""),"PLD"),"")),""),""),IF(V20<>"",IF(Parametre_2018!O$4<>"",IF(N20<=Parametre_2018!O$4,IF(V20<>"",IF(Parametre_2018!P$4<>"",IF(O20<=Parametre_2018!P$4,"PLD",""),"PLD"),""),""),IF(V20<>"",IF(Parametre_2018!P$4<>"",IF(O20<=Parametre_2018!P$4,"PLD",""),"PLD"),"")),"")),"")),IF(V20<>"",IF(Parametre_2018!N$4=1,IF(LEFT(V20,1)="1",IF(V20<>"",IF(Parametre_2018!O$4<>"",IF(N20<=Parametre_2018!O$4,IF(V20<>"",IF(Parametre_2018!P$4<>"",IF(O20<=Parametre_2018!P$4,"PLD",""),"PLD"),""),""),IF(V20<>"",IF(Parametre_2018!P$4<>"",IF(O20<=Parametre_2018!P$4,"PLD",""),"PLD"),"")),""),""),IF(V20<>"",IF(Parametre_2018!O$4<>"",IF(N20<=Parametre_2018!O$4,IF(V20<>"",IF(Parametre_2018!P$4<>"",IF(O20<=Parametre_2018!P$4,"PLD",""),"PLD"),""),""),IF(V20<>"",IF(Parametre_2018!P$4<>"",IF(O20<=Parametre_2018!P$4,"PLD",""),"PLD"),"")),"")),"")),"") -> PLD | Z20: PLD | AA20: PLD | AB20: =IF(Q20<>"",IF(Q20<=Parametre_2018!B$4,IF(Parametre_2018!C$4<>"",IF(N20<=Parametre_2018!C$4,IF(Parametre_2018!D$4<>"",IF(O20<=Parametre_2018!D$4,"MCL",IF(Parametre_2018!I$4<>"",IF(N20<=Parametre_2018!I$4,IF(Parametre_2018!J$4<>"",IF(O20<=Parametre_2018!J$4,"CL",""),"CL"),""),IF(Parametre_2018!J$4<>"",IF(O20<=Parametre_2018!J$4,"CL",""),"CL"))),"MCL"),IF(Parametre_2018!I$4<>"",IF(N20<=Parametre_2018!I$4,IF(Parametre_2018!J$4<>"",IF(O20<=Parametre_2018!J$4,"CL",""),"CL"),""),IF(Parametre_2018!J$4<>"",IF(O20<=Parametre_2018!J$4,"CL",""),"CL"))),IF(Parametre_2018!D$4<>"",IF(O20<=Parametre_2018!D$4,"MCL",IF(Parametre_2018!I$4<>"",IF(N20<=Parametre_2018!I$4,IF(Parametre_2018!J$4<>"",IF(O20<=Parametre_2018!J$4,"CL",""),"CL"),""),IF(Parametre_2018!J$4<>"",IF(O20<=Parametre_2018!J$4,"CL",""),"CL"))),"MCL")),IF(Q20<>"",IF(AND(Q20>Parametre_2018!B$4,Q20<=Parametre_2018!H$4),IF(Parametre_2018!I$4<>"",IF(N20<=Parametre_2018!I$4,IF(Parametre_2018!J$4<>"",IF(O20<=Parametre_2018!J$4,"CL",""),"CL"),""),IF(Parametre_2018!J$4<>"",IF(O20<=Parametre_2018!J$4,"CL",""),"CL")),""),"")),"") | AE20: IT Spy
A21: 85 | B21: A | C21: Pomffyová | D21: Miriama | E21: Bc. | F21: IS 2 | G21: 43263 | H21: 4u-IS | I21: Rozinajová | J21: Vrablecová | K21: Inteligentná analýza dát v prostredí energetiky | L21: doc. Ing. Viera Rozinajová, PhD. | M21: Mgr. Peter Laurinec | N21: B | O21: A | P21: 1.63 | Q21: 1.5 | R21: D-IIS | U21: =IF(OR(V21<>"",Y21<>"",AB21<>""),"Navrh","") -> Navrh | V21: 1 | Y21: =IF(Q21<>"",IF(Q21<=1.2,IF(O21="A","CR",IF(V21<>"",IF(Parametre_2018!N$4=1,IF(LEFT(V21,1)="1",IF(V21<>"",IF(Parametre_2018!O$4<>"",IF(N21<=Parametre_2018!O$4,IF(V21<>"",IF(Parametre_2018!P$4<>"",IF(O21<=Parametre_2018!P$4,"PLD",""),"PLD"),""),""),IF(V21<>"",IF(Parametre_2018!P$4<>"",IF(O21<=Parametre_2018!P$4,"PLD",""),"PLD"),"")),""),""),IF(V21<>"",IF(Parametre_2018!O$4<>"",IF(N21<=Parametre_2018!O$4,IF(V21<>"",IF(Parametre_2018!P$4<>"",IF(O21<=Parametre_2018!P$4,"PLD",""),"PLD"),""),""),IF(V21<>"",IF(Parametre_2018!P$4<>"",IF(O21<=Parametre_2018!P$4,"PLD",""),"PLD"),"")),"")),"")),IF(V21<>"",IF(Parametre_2018!N$4=1,IF(LEFT(V21,1)="1",IF(V21<>"",IF(Parametre_2018!O$4<>"",IF(N21<=Parametre_2018!O$4,IF(V21<>"",IF(Parametre_2018!P$4<>"",IF(O21<=Parametre_2018!P$4,"PLD",""),"PLD"),""),""),IF(V21<>"",IF(Parametre_2018!P$4<>"",IF(O21<=Parametre_2018!P$4,"PLD",""),"PLD"),"")),""),""),IF(V21<>"",IF(Parametre_2018!O$4<>"",IF(N21<=Parametre_2018!O$4,IF(V21<>"",IF(Parametre_2018!P$4<>"",IF(O21<=Parametre_2018!P$4,"PLD",""),"PLD"),""),""),IF(V21<>"",IF(Parametre_2018!P$4<>"",IF(O21<=Parametre_2018!P$4,"PLD",""),"PLD"),"")),"")),"")),"") -> PLD | Z21: PLD | AA21: PLD | AB21: =IF(Q21<>"",IF(Q21<=Parametre_2018!B$4,IF(Parametre_2018!C$4<>"",IF(N21<=Parametre_2018!C$4,IF(Parametre_2018!D$4<>"",IF(O21<=Parametre_2018!D$4,"MCL",IF(Parametre_2018!I$4<>"",IF(N21<=Parametre_2018!I$4,IF(Parametre_2018!J$4<>"",IF(O21<=Parametre_2018!J$4,"CL",""),"CL"),""),IF(Parametre_2018!J$4<>"",IF(O21<=Parametre_2018!J$4,"CL",""),"CL"))),"MCL"),IF(Parametre_2018!I$4<>"",IF(N21<=Parametre_2018!I$4,IF(Parametre_2018!J$4<>"",IF(O21<=Parametre_2018!J$4,"CL",""),"CL"),""),IF(Parametre_2018!J$4<>"",IF(O21<=Parametre_2018!J$4,"CL",""),"CL"))),IF(Parametre_2018!D$4<>"",IF(O21<=Parametre_2018!D$4,"MCL",IF(Parametre_2018!I$4<>"",IF(N21<=Parametre_2018!I$4,IF(Parametre_2018!J$4<>"",IF(O21<=Parametre_2018!J$4,"CL",""),"CL"),""),IF(Parametre_2018!J$4<>"",IF(O21<=Parametre_2018!J$4,"CL",""),"CL"))),"MCL")),IF(Q21<>"",IF(AND(Q21>Parametre_2018!B$4,Q21<=Parametre_2018!H$4),IF(Parametre_2018!I$4<>"",IF(N21<=Parametre_2018!I$4,IF(Parametre_2018!J$4<>"",IF(O21<=Parametre_2018!J$4,"CL",""),"CL"),""),IF(Parametre_2018!J$4<>"",IF(O21<=Parametre_2018!J$4,"CL",""),"CL")),""),"")),"")
A22: 103 | B22: A | C22: Šrank | D22: Martin | E22: Bc. | F22: IS 2 | G22: 43262 | H22: 4p-IS-SI | I22: Rozinajová | J22: Gašpar | K22: Podpora diverzity a aktuálnosti informačných bulletinov v systéme pre odpovedanie na otázky | L22: Ing. Ivan Srba, PhD. | M22: Ing. Ondrej Kaššák, PhD. | N22: A | O22: A | P22: 1.62 | Q22: 1.55 | U22: =IF(OR(V22<>"",Y22<>"",AB22<>""),"Navrh","") | X22: A | Y22: =IF(Q22<>"",IF(Q22<=1.2,IF(O22="A","CR",IF(V22<>"",IF(Parametre_2018!N$4=1,IF(LEFT(V22,1)="1",IF(V22<>"",IF(Parametre_2018!O$4<>"",IF(N22<=Parametre_2018!O$4,IF(V22<>"",IF(Parametre_2018!P$4<>"",IF(O22<=Parametre_2018!P$4,"PLD",""),"PLD"),""),""),IF(V22<>"",IF(Parametre_2018!P$4<>"",IF(O22<=Parametre_2018!P$4,"PLD",""),"PLD"),"")),""),""),IF(V22<>"",IF(Parametre_2018!O$4<>"",IF(N22<=Parametre_2018!O$4,IF(V22<>"",IF(Parametre_2018!P$4<>"",IF(O22<=Parametre_2018!P$4,"PLD",""),"PLD"),""),""),IF(V22<>"",IF(Parametre_2018!P$4<>"",IF(O22<=Parametre_2018!P$4,"PLD",""),"PLD"),"")),"")),"")),IF(V22<>"",IF(Parametre_2018!N$4=1,IF(LEFT(V22,1)="1",IF(V22<>"",IF(Parametre_2018!O$4<>"",IF(N22<=Parametre_2018!O$4,IF(V22<>"",IF(Parametre_2018!P$4<>"",IF(O22<=Parametre_2018!P$4,"PLD",""),"PLD"),""),""),IF(V22<>"",IF(Parametre_2018!P$4<>"",IF(O22<=Parametre_2018!P$4,"PLD",""),"PLD"),"")),""),""),IF(V22<>"",IF(Parametre_2018!O$4<>"",IF(N22<=Parametre_2018!O$4,IF(V22<>"",IF(Parametre_2018!P$4<>"",IF(O22<=Parametre_2018!P$4,"PLD",""),"PLD"),""),""),IF(V22<>"",IF(Parametre_2018!P$4<>"",IF(O22<=Parametre_2018!P$4,"PLD",""),"PLD"),"")),"")),"")),"") | AB22: =IF(Q22<>"",IF(Q22<=Parametre_2018!B$4,IF(Parametre_2018!C$4<>"",IF(N22<=Parametre_2018!C$4,IF(Parametre_2018!D$4<>"",IF(O22<=Parametre_2018!D$4,"MCL",IF(Parametre_2018!I$4<>"",IF(N22<=Parametre_2018!I$4,IF(Parametre_2018!J$4<>"",IF(O22<=Parametre_2018!J$4,"CL",""),"CL"),""),IF(Parametre_2018!J$4<>"",IF(O22<=Parametre_2018!J$4,"CL",""),"CL"))),"MCL"),IF(Parametre_2018!I$4<>"",IF(N22<=Parametre_2018!I$4,IF(Parametre_2018!J$4<>"",IF(O22<=Parametre_2018!J$4,"CL",""),"CL"),""),IF(Parametre_2018!J$4<>"",IF(O22<=Parametre_2018!J$4,"CL",""),"CL"))),IF(Parametre_2018!D$4<>"",IF(O22<=Parametre_2018!D$4,"MCL",IF(Parametre_2018!I$4<>"",IF(N22<=Parametre_2018!I$4,IF(Parametre_2018!J$4<>"",IF(O22<=Parametre_2018!J$4,"CL",""),"CL"),""),IF(Parametre_2018!J$4<>"",IF(O22<=Parametre_2018!J$4,"CL",""),"CL"))),"MCL")),IF(Q22<>"",IF(AND(Q22>Parametre_2018!B$4,Q22<=Parametre_2018!H$4),IF(Parametre_2018!I$4<>"",IF(N22<=Parametre_2018!I$4,IF(Parametre_2018!J$4<>"",IF(O22<=Parametre_2018!J$4,"CL",""),"CL"),""),IF(Parametre_2018!J$4<>"",IF(O22<=Parametre_2018!J$4,"CL",""),"CL")),""),"")),"")
A23: 107 | B23: N | C23: Tóth | D23: Jaroslav | E23: Bc. | F23: SI 2 | G23: 43262 | H23: 8p-SI | I23: Kotuliak | J23: Košťál | K23: Predikcia parametrov sieťovej premávky v softvérovo definovaných sieťach | L23: Ing. Ján Lúčanský | M23: Ing. Rudolf Grežo | N23: A | O23: A | P23: 1.6 | Q23: 1.55 | S23: A | U23: =IF(OR(V23<>"",Y23<>"",AB23<>""),"Navrh","") | Y23: =IF(Q23<>"",IF(Q23<=1.2,IF(O23="A","CR",IF(V23<>"",IF(Parametre_2018!N$4=1,IF(LEFT(V23,1)="1",IF(V23<>"",IF(Parametre_2018!O$4<>"",IF(N23<=Parametre_2018!O$4,IF(V23<>"",IF(Parametre_2018!P$4<>"",IF(O23<=Parametre_2018!P$4,"PLD",""),"PLD"),""),""),IF(V23<>"",IF(Parametre_2018!P$4<>"",IF(O23<=Parametre_2018!P$4,"PLD",""),"PLD"),"")),""),""),IF(V23<>"",IF(Parametre_2018!O$4<>"",IF(N23<=Parametre_2018!O$4,IF(V23<>"",IF(Parametre_2018!P$4<>"",IF(O23<=Parametre_2018!P$4,"PLD",""),"PLD"),""),""),IF(V23<>"",IF(Parametre_2018!P$4<>"",IF(O23<=Parametre_2018!P$4,"PLD",""),"PLD"),"")),"")),"")),IF(V23<>"",IF(Parametre_2018!N$4=1,IF(LEFT(V23,1)="1",IF(V23<>"",IF(Parametre_2018!O$4<>"",IF(N23<=Parametre_2018!O$4,IF(V23<>"",IF(Parametre_2018!P$4<>"",IF(O23<=Parametre_2018!P$4,"PLD",""),"PLD"),""),""),IF(V23<>"",IF(Parametre_2018!P$4<>"",IF(O23<=Parametre_2018!P$4,"PLD",""),"PLD"),"")),""),""),IF(V23<>"",IF(Parametre_2018!O$4<>"",IF(N23<=Parametre_2018!O$4,IF(V23<>"",IF(Parametre_2018!P$4<>"",IF(O23<=Parametre_2018!P$4,"PLD",""),"PLD"),""),""),IF(V23<>"",IF(Parametre_2018!P$4<>"",IF(O23<=Parametre_2018!P$4,"PLD",""),"PLD"),"")),"")),"")),"") | AB23: =IF(Q23<>"",IF(Q23<=Parametre_2018!B$4,IF(Parametre_2018!C$4<>"",IF(N23<=Parametre_2018!C$4,IF(Parametre_2018!D$4<>"",IF(O23<=Parametre_2018!D$4,"MCL",IF(Parametre_2018!I$4<>"",IF(N23<=Parametre_2018!I$4,IF(Parametre_2018!J$4<>"",IF(O23<=Parametre_2018!J$4,"CL",""),"CL"),""),IF(Parametre_2018!J$4<>"",IF(O23<=Parametre_2018!J$4,"CL",""),"CL"))),"MCL"),IF(Parametre_2018!I$4<>"",IF(N23<=Parametre_2018!I$4,IF(Parametre_2018!J$4<>"",IF(O23<=Parametre_2018!J$4,"CL",""),"CL"),""),IF(Parametre_2018!J$4<>"",IF(O23<=Parametre_2018!J$4,"CL",""),"CL"))),IF(Parametre_2018!D$4<>"",IF(O23<=Parametre_2018!D$4,"MCL",IF(Parametre_2018!I$4<>"",IF(N23<=Parametre_2018!I$4,IF(Parametre_2018!J$4<>"",IF(O23<=Parametre_2018!J$4,"CL",""),"CL"),""),IF(Parametre_2018!J$4<>"",IF(O23<=Parametre_2018!J$4,"CL",""),"CL"))),"MCL")),IF(Q23<>"",IF(AND(Q23>Parametre_2018!B$4,Q23<=Parametre_2018!H$4),IF(Parametre_2018!I$4<>"",IF(N23<=Parametre_2018!I$4,IF(Parametre_2018!J$4<>"",IF(O23<=Parametre_2018!J$4,"CL",""),"CL"),""),IF(Parametre_2018!J$4<>"",IF(O23<=Parametre_2018!J$4,"CL",""),"CL")),""),"")),"")
A24: 57 | B24: A | C24: Kráľ | D24: Michal | E24: Bc. | F24: SI 2 | G24: 43262 | H24: 5p-SI | I24: Vranič | J24: Jarábek | K24: Identifikácia, kompozícia a konfigurácia existujúcich softvérových komponentov podľa špecifikácie požiadaviek vo forme textu | L24: Ing. Michal Bystrický | M24: doc. Ing. Valentino Vranić, PhD. | N24: A | O24: A | P24: 1.61 | Q24: 1.56 | U24: =IF(OR(V24<>"",Y24<>"",AB24<>""),"Navrh","") -> Navrh | V24: 1 | X24: A | Y24: =IF(Q24<>"",IF(Q24<=1.2,IF(O24="A","CR",IF(V24<>"",IF(Parametre_2018!N$4=1,IF(LEFT(V24,1)="1",IF(V24<>"",IF(Parametre_2018!O$4<>"",IF(N24<=Parametre_2018!O$4,IF(V24<>"",IF(Parametre_2018!P$4<>"",IF(O24<=Parametre_2018!P$4,"PLD",""),"PLD"),""),""),IF(V24<>"",IF(Parametre_2018!P$4<>"",IF(O24<=Parametre_2018!P$4,"PLD",""),"PLD"),"")),""),""),IF(V24<>"",IF(Parametre_2018!O$4<>"",IF(N24<=Parametre_2018!O$4,IF(V24<>"",IF(Parametre_2018!P$4<>"",IF(O24<=Parametre_2018!P$4,"PLD",""),"PLD"),""),""),IF(V24<>"",IF(Parametre_2018!P$4<>"",IF(O24<=Parametre_2018!P$4,"PLD",""),"PLD"),"")),"")),"")),IF(V24<>"",IF(Parametre_2018!N$4=1,IF(LEFT(V24,1)="1",IF(V24<>"",IF(Parametre_2018!O$4<>"",IF(N24<=Parametre_2018!O$4,IF(V24<>"",IF(Parametre_2018!P$4<>"",IF(O24<=Parametre_2018!P$4,"PLD",""),"PLD"),""),""),IF(V24<>"",IF(Parametre_2018!P$4<>"",IF(O24<=Parametre_2018!P$4,"PLD",""),"PLD"),"")),""),""),IF(V24<>"",IF(Parametre_2018!O$4<>"",IF(N24<=Parametre_2018!O$4,IF(V24<>"",IF(Parametre_2018!P$4<>"",IF(O24<=Parametre_2018!P$4,"PLD",""),"PLD"),""),""),IF(V24<>"",IF(Parametre_2018!P$4<>"",IF(O24<=Parametre_2018!P$4,"PLD",""),"PLD"),"")),"")),"")),"") -> PLD | Z24: PLD | AA24: PLD | AB24: =IF(Q24<>"",IF(Q24<=Parametre_2018!B$4,IF(Parametre_2018!C$4<>"",IF(N24<=Parametre_2018!C$4,IF(Parametre_2018!D$4<>"",IF(O24<=Parametre_2018!D$4,"MCL",IF(Parametre_2018!I$4<>"",IF(N24<=Parametre_2018!I$4,IF(Parametre_2018!J$4<>"",IF(O24<=Parametre_2018!J$4,"CL",""),"CL"),""),IF(Parametre_2018!J$4<>"",IF(O24<=Parametre_2018!J$4,"CL",""),"CL"))),"MCL"),IF(Parametre_2018!I$4<>"",IF(N24<=Parametre_2018!I$4,IF(Parametre_2018!J$4<>"",IF(O24<=Parametre_2018!J$4,"CL",""),"CL"),""),IF(Parametre_2018!J$4<>"",IF(O24<=Parametre_2018!J$4,"CL",""),"CL"))),IF(Parametre_2018!D$4<>"",IF(O24<=Parametre_2018!D$4,"MCL",IF(Parametre_2018!I$4<>"",IF(N24<=Parametre_2018!I$4,IF(Parametre_2018!J$4<>"",IF(O24<=Parametre_2018!J$4,"CL",""),"CL"),""),IF(Parametre_2018!J$4<>"",IF(O24<=Parametre_2018!J$4,"CL",""),"CL"))),"MCL")),IF(Q24<>"",IF(AND(Q24>Parametre_2018!B$4,Q24<=Parametre_2018!H$4),IF(Parametre_2018!I$4<>"",IF(N24<=Parametre_2018!I$4,IF(Parametre_2018!J$4<>"",IF(O24<=Parametre_2018!J$4,"CL",""),"CL"),""),IF(Parametre_2018!J$4<>"",IF(O24<=Parametre_2018!J$4,"CL",""),"CL")),""),"")),"") | AE24: IT Spy
A25: 6 | B25: A | C25: Berger | D25: Patrik | E25: Bc. | F25: IS 2 | G25: 43262 | H25: 4p-IS-SI | I25: Rozinajová | J25: Gašpar | K25: Predikcia retencie zákazníkov v online prostredí | L25: doc. Ing. Michal Kompan, PhD. | M25: Ing. Michal Barla, PhD. | N25: A | O25: A | P25: 1.63 | Q25: 1.58 | U25: =IF(OR(V25<>"",Y25<>"",AB25<>""),"Navrh","") | W25: A | X25: A | Y25: =IF(Q25<>"",IF(Q25<=1.2,IF(O25="A","CR",IF(V25<>"",IF(Parametre_2018!N$4=1,IF(LEFT(V25,1)="1",IF(V25<>"",IF(Parametre_2018!O$4<>"",IF(N25<=Parametre_2018!O$4,IF(V25<>"",IF(Parametre_2018!P$4<>"",IF(O25<=Parametre_2018!P$4,"PLD",""),"PLD"),""),""),IF(V25<>"",IF(Parametre_2018!P$4<>"",IF(O25<=Parametre_2018!P$4,"PLD",""),"PLD"),"")),""),""),IF(V25<>"",IF(Parametre_2018!O$4<>"",IF(N25<=Parametre_2018!O$4,IF(V25<>"",IF(Parametre_2018!P$4<>"",IF(O25<=Parametre_2018!P$4,"PLD",""),"PLD"),""),""),IF(V25<>"",IF(Parametre_2018!P$4<>"",IF(O25<=Parametre_2018!P$4,"PLD",""),"PLD"),"")),"")),"")),IF(V25<>"",IF(Parametre_2018!N$4=1,IF(LEFT(V25,1)="1",IF(V25<>"",IF(Parametre_2018!O$4<>"",IF(N25<=Parametre_2018!O$4,IF(V25<>"",IF(Parametre_2018!P$4<>"",IF(O25<=Parametre_2018!P$4,"PLD",""),"PLD"),""),""),IF(V25<>"",IF(Parametre_2018!P$4<>"",IF(O25<=Parametre_2018!P$4,"PLD",""),"PLD"),"")),""),""),IF(V25<>"",IF(Parametre_2018!O$4<>"",IF(N25<=Parametre_2018!O$4,IF(V25<>"",IF(Parametre_2018!P$4<>"",IF(O25<=Parametre_2018!P$4,"PLD",""),"PLD"),""),""),IF(V25<>"",IF(Parametre_2018!P$4<>"",IF(O25<=Parametre_2018!P$4,"PLD",""),"PLD"),"")),"")),"")),"") | AB25: =IF(Q25<>"",IF(Q25<=Parametre_2018!B$4,IF(Parametre_2018!C$4<>"",IF(N25<=Parametre_2018!C$4,IF(Parametre_2018!D$4<>"",IF(O25<=Parametre_2018!D$4,"MCL",IF(Parametre_2018!I$4<>"",IF(N25<=Parametre_2018!I$4,IF(Parametre_2018!J$4<>"",IF(O25<=Parametre_2018!J$4,"CL",""),"CL"),""),IF(Parametre_2018!J$4<>"",IF(O25<=Parametre_2018!J$4,"CL",""),"CL"))),"MCL"),IF(Parametre_2018!I$4<>"",IF(N25<=Parametre_2018!I$4,IF(Parametre_2018!J$4<>"",IF(O25<=Parametre_2018!J$4,"CL",""),"CL"),""),IF(Parametre_2018!J$4<>"",IF(O25<=Parametre_2018!J$4,"CL",""),"CL"))),IF(Parametre_2018!D$4<>"",IF(O25<=Parametre_2018!D$4,"MCL",IF(Parametre_2018!I$4<>"",IF(N25<=Parametre_2018!I$4,IF(Parametre_2018!J$4<>"",IF(O25<=Parametre_2018!J$4,"CL",""),"CL"),""),IF(Parametre_2018!J$4<>"",IF(O25<=Parametre_2018!J$4,"CL",""),"CL"))),"MCL")),IF(Q25<>"",IF(AND(Q25>Parametre_2018!B$4,Q25<=Parametre_2018!H$4),IF(Parametre_2018!I$4<>"",IF(N25<=Parametre_2018!I$4,IF(Parametre_2018!J$4<>"",IF(O25<=Parametre_2018!J$4,"CL",""),"CL"),""),IF(Parametre_2018!J$4<>"",IF(O25<=Parametre_2018!J$4,"CL",""),"CL")),""),"")),"")
